<?xml version="1.0"?>
<robot name="robotiq_arg2f_85" xmlns:xacro="http://ros.org/wiki/xacro">

  <xacro:macro name="outer_knuckle" params="prefix fingerprefix stroke">
    <link name="${prefix}_${fingerprefix}_outer_knuckle">
      <inertial>
        <origin xyz="-0.000200000000003065 0.0199435877845359 0.0292245259211331" rpy="0 0 0" />
        <mass value="0.00853198276973456" />
        <inertia ixx="2.89328108496468E-06" ixy="-1.57935047237397E-19" ixz="-1.93980378593255E-19" iyy="1.86719750325683E-06" iyz="-1.21858577871576E-06" izz="1.21905238907251E-06" />
      </inertial>
      <visual>
        <origin xyz="0 0 0" rpy="0 0 0" />
        <geometry>
          <mesh filename="package://dual_description/meshes/visual/robotiq/robotiq_arg2f_85_outer_knuckle.dae" scale="0.001 0.001 0.001"/>
        </geometry>
        <material name="">
          <color rgba="0.792156862745098 0.819607843137255 0.933333333333333 1" />
        </material>
      </visual>
      <collision>0.0
        <origin xyz="0 0 0" rpy="0 0 0" />
        <geometry>
          <mesh filename="package://dual_description/meshes/collision/robotiq/robotiq_arg2f_85_outer_knuckle.dae" scale="0.001 0.001 0.001"/>
        </geometry>
      </collision>
    </link>
  </xacro:macro>

  <xacro:macro name="outer_finger" params="prefix fingerprefix stroke">
    <link name="${prefix}_${fingerprefix}_outer_finger">
      <inertial>
        <origin xyz="0.00030115855001899 0.0373907951953854 -0.0208027427000385" rpy="0 0 0" />
        <mass value="0.022614240507152" />
        <inertia ixx="1.52518312458174E-05" ixy="9.76583423954399E-10" ixz="-5.43838577022588E-10" iyy="6.17694243867776E-06" iyz="6.78636130740228E-06" izz="1.16494917907219E-05" />
      </inertial>
      <visual>
        <origin xyz="0 0 0" rpy="0 0 0" />
        <geometry>
          <mesh filename="package://dual_description/meshes/visual/robotiq/robotiq_arg2f_85_outer_finger.dae" scale="0.001 0.001 0.001"/>
        </geometry>
        <material name="">
          <color rgba="0.1 0.1 0.1 1" />
        </material>
      </visual>
      <collision>
        <origin xyz="0 0 0" rpy="0 0 0" />
        <geometry>
          <mesh filename="package://dual_description/meshes/collision/robotiq/robotiq_arg2f_85_outer_finger.dae" scale="0.001 0.001 0.001"/>
        </geometry>
      </collision>
    </link>
  </xacro:macro>

  <xacro:macro name="inner_knuckle" params="prefix fingerprefix stroke">
    <link name="${prefix}_${fingerprefix}_inner_knuckle">
      <inertial>
        <origin xyz="0.000123011831763771 0.0507850843201817 0.00103968640075166" rpy="0 0 0" />
        <mass value="0.0271177346495152" />
        <inertia ixx="2.61910379223783E-05" ixy="-2.43616858946494E-07" ixz="-6.37789906117123E-09" iyy="2.8270243746167E-06" iyz="-5.37200748039765E-07" izz="2.83695868220296E-05" />
      </inertial>
      <visual>
        <origin xyz="0 0 0" rpy="0 0 0" />
        <geometry>
          <mesh filename="package://dual_description/meshes/visual/robotiq/robotiq_arg2f_85_inner_knuckle.dae" scale="0.001 0.001 0.001"/>
        </geometry>
        <material name="">
          <color rgba="0.1 0.1 0.1 1" />
        </material>
      </visual>
      <collision>
        <origin xyz="0 0 0" rpy="0 0 0" />
        <geometry>
          <mesh filename="package://dual_description/meshes/collision/robotiq/robotiq_arg2f_85_inner_knuckle.dae" scale="0.001 0.001 0.001"/>
        </geometry>
      </collision>
    </link>
  </xacro:macro>

  <xacro:macro name="inner_finger" params="prefix fingerprefix stroke">
    <link name="${prefix}_${fingerprefix}_inner_finger">
      <inertial>
        <origin xyz="0.000299999999999317 0.0160078233491243 -0.0136945669206257" rpy="0 0 0" />
        <mass value="0.0104003125914103" />
        <inertia ixx="2.71909453810972E-06" ixy="1.35402465472579E-21" ixz="-7.1817349065269E-22" iyy="7.69100314106116E-07" iyz="6.74715432769696E-07" izz="2.30315190420171E-06" />
      </inertial>
      <visual>
        <origin xyz="0 0 0" rpy="0 0 0" />
        <geometry>
          <mesh filename="package://dual_description/meshes/visual/robotiq/robotiq_arg2f_85_inner_finger.dae" scale="0.001 0.001 0.001"/>
        </geometry>
        <material name="">
          <color rgba="0.1 0.1 0.1 1" />
        </material>
      </visual>
      <collision>
        <origin xyz="0 0 0" rpy="0 0 0" />
        <geometry>
          <mesh filename="package://dual_description/meshes/collision/robotiq/robotiq_arg2f_85_inner_finger.dae" scale="0.001 0.001 0.001" />
        </geometry>
      </collision>
    </link>
  </xacro:macro>

   <!-- Finger pad link, the default are the "big pads" with rubber-->
  <xacro:macro name="inner_finger_pad" params="prefix fingerprefix">
    <link name="${prefix}_${fingerprefix}_inner_finger_pad">
      <visual>
        <origin xyz="0 0 0" rpy="0 0 0" />
        <geometry>
          <box size="0.022 0.00635 0.0375"/>
        </geometry>
        <material name="">
          <color rgba="0.9 0.9 0.9 1" />
        </material>
      </visual>
      <collision>
        <origin xyz="0 0 0" rpy="0 0 0" />
        <geometry>
           <box size="0.022 0.00635 0.0375"/>
        </geometry>
        <material name="">
          <color rgba="0.9 0.0 0.0 1" />
        </material>
      </collision>
    </link>
  </xacro:macro>

  <xacro:macro name="outer_finger_joint" params="prefix fingerprefix">
    <joint name="${prefix}_${fingerprefix}_outer_finger_joint" type="fixed">
      <origin xyz="0 0.0315 -0.0041" rpy="0 0 0"/>
      <parent link="${prefix}_${fingerprefix}_outer_knuckle" />
      <child link="${prefix}_${fingerprefix}_outer_finger" />
      <axis xyz="1 0 0" />
    </joint>
  </xacro:macro>

  <xacro:macro name="inner_knuckle_joint" params="prefix fingerprefix reflect">
    <joint name="${prefix}_${fingerprefix}_inner_knuckle_joint" type="revolute">
      <!-- <origin xyz="0 ${reflect * -0.0127} 0.06142" rpy="${pi / 2 + .725} 0 ${(reflect - 1) * pi / 2}" /> -->
      <origin xyz="0 ${reflect * -0.0127} 0.06142" rpy="0 0 ${(1 + reflect) * pi / 2}"/>
      <parent link="${prefix}_base_link" />
      <child link="${prefix}_${fingerprefix}_inner_knuckle" />
      <axis xyz="1 0 0" />
      <limit lower="0" upper="0.8757" velocity="2.0" effort="1000" />
      <mimic joint="${prefix}_left_finger_joint" multiplier="1" offset="0" />
    </joint>
  </xacro:macro>

  <xacro:macro name="inner_finger_joint" params="prefix fingerprefix">
    <joint name="${prefix}_${fingerprefix}_inner_finger_joint" type="revolute">
      <origin xyz="0 0.0061 0.0471" rpy="0 0 0"/>
      <parent link="${prefix}_${fingerprefix}_outer_finger" />
      <child link="${prefix}_${fingerprefix}_inner_finger" />
      <axis xyz="1 0 0" />
      <limit lower="-0.8757" upper="0.8757" velocity="2.0" effort="1000" />
      <mimic joint="${prefix}_left_finger_joint" multiplier="-1" offset="0" />
    </joint>
  </xacro:macro>

  <xacro:macro name="inner_finger_pad_joint" params="prefix fingerprefix">
    <joint name="${prefix}_${fingerprefix}_inner_finger_pad_joint" type="fixed">
      <origin xyz="0 -0.0220203446692936 0.03242" rpy="0 0 0"/>
      <parent link="${prefix}_${fingerprefix}_inner_finger" />
      <child link="${prefix}_${fingerprefix}_inner_finger_pad" />
      <axis xyz="0 0 1" />
    </joint>
  </xacro:macro>

  <xacro:macro name="base_link" params="prefix">
    <link name="${prefix}_base_link">
      <inertial>
        <origin xyz="8.625E-08 -4.6583E-06 0.03145" rpy="0 0 0" />
        <mass value="0.22652" />
        <inertia ixx="0.00020005" ixy="-4.2442E-10" ixz="-2.9069E-10" iyy="0.00017832" iyz="-3.4402E-08" izz="0.00013478" />
      </inertial>
      <visual>
        <origin xyz="0 0 0" rpy="0 0 0" />
        <geometry>
          <mesh filename="package://dual_description/meshes/collision/robotiq/robotiq_arg2f_base_link.stl"/>
        </geometry>
        <material name="grey"/>
      </visual>
      <collision>
        <origin xyz="0 0 0" rpy="0 0 0" />
        <geometry>
           <mesh filename="package://dual_description/meshes/collision/robotiq/robotiq_arg2f_base_link.stl" />
        </geometry>
      </collision>
    </link>
  </xacro:macro>

  <xacro:macro name="finger_joints" params="prefix fingerprefix reflect">
    <xacro:outer_finger_joint prefix="${prefix}" fingerprefix="${fingerprefix}"/>
    <xacro:inner_knuckle_joint prefix="${prefix}" fingerprefix="${fingerprefix}" reflect="${reflect}"/>
    <xacro:inner_finger_joint prefix="${prefix}" fingerprefix="${fingerprefix}"/>
    <xacro:inner_finger_pad_joint prefix="${prefix}" fingerprefix="${fingerprefix}"/>
  </xacro:macro>

  <xacro:macro name="finger_links" params="prefix fingerprefix stroke">
    <xacro:outer_knuckle prefix="${prefix}" fingerprefix="${fingerprefix}" stroke="${stroke}"/>
    <xacro:outer_finger prefix="${prefix}" fingerprefix="${fingerprefix}" stroke="${stroke}"/>
    <xacro:inner_finger prefix="${prefix}" fingerprefix="${fingerprefix}" stroke="${stroke}"/>
    <xacro:inner_finger_pad prefix="${prefix}" fingerprefix="${fingerprefix}"/>
    <xacro:inner_knuckle prefix="${prefix}" fingerprefix="${fingerprefix}" stroke="${stroke}"/>
  </xacro:macro>

  <xacro:macro name="left_finger_joint" params="prefix">
    <joint name="${prefix}_left_finger_joint" type="revolute">
      <origin xyz="0 -0.0306011 0.054904" rpy="0 0 ${pi}"/>
      <parent link="${prefix}_base_link" />
      <child link="${prefix}_left_outer_knuckle" />
      <axis xyz="1 0 0" />
      <limit lower="0" upper="0.8" velocity="2.0" effort="1000" />
    </joint>
    <xacro:finger_joints prefix="${prefix}" fingerprefix="left" reflect="1.0"/>
  </xacro:macro>

  <xacro:macro name="right_finger_joint" params="prefix">
    <joint name="${prefix}_right_finger_joint" type="revolute">
      <origin xyz="0 0.0306011 0.054904" rpy="0 0 0"/>
      <parent link="${prefix}_base_link" />
      <child link="${prefix}_right_outer_knuckle" />
      <axis xyz="1 0 0" />
      <limit lower="0" upper="0.81" velocity="2.0" effort="1000" />
      <mimic joint="${prefix}_left_finger_joint" multiplier="1" offset="0" />
    </joint>
    <xacro:finger_joints prefix="${prefix}" fingerprefix="right" reflect="-1.0"/>
  </xacro:macro>

  <xacro:macro name="robotiq_arg2f_transmission" params="prefix">
    <transmission name="${prefix}_finger_joint_trans">
      <type>transmission_interface/SimpleTransmission</type>
      <joint name="${prefix}_left_finger_joint">
        <hardwareInterface>PositionJointInterface</hardwareInterface>
      </joint>
      <actuator name="${prefix}_finger_joint_motor">
        <mechanicalReduction>1</mechanicalReduction>
      </actuator>
    </transmission>
  </xacro:macro>

  <xacro:macro name="inner_mimic_gazebo" params="prefix fingerprefix">
    <gazebo>
      <plugin filename="libroboticsgroup_upatras_gazebo_mimic_joint_plugin.so" name="${prefix}_${fingerprefix}_inner_knuckle_mimic">
        <joint>${prefix}_left_finger_joint</joint>
        <mimicJoint>${prefix}_${fingerprefix}_inner_knuckle_joint</mimicJoint>
        <multiplier>1.0</multiplier>
      </plugin>
      <plugin filename="libroboticsgroup_upatras_gazebo_mimic_joint_plugin.so" name="${prefix}_${fingerprefix}_inner_finger_mimic">
        <joint>${prefix}_left_finger_joint</joint>
        <mimicJoint>${prefix}_${fingerprefix}_inner_finger_joint</mimicJoint>
        <multiplier>-1.0</multiplier>
      </plugin>
    </gazebo>
  </xacro:macro>

  <xacro:macro name="right_finger_mimic_gazebo" params="prefix">
    <gazebo>
      <plugin filename="libroboticsgroup_upatras_gazebo_mimic_joint_plugin.so" name="${prefix}_right_finger_mimic">
        <joint>${prefix}_left_finger_joint</joint>
        <mimicJoint>${prefix}_right_finger_joint</mimicJoint>
        <multiplier>1.0</multiplier>
      </plugin>
    </gazebo>
  </xacro:macro>

  <!-- Initialization of all joints and links -->
  <xacro:macro name="robotiq_arg2f_85" params="gripper_name:='robotiq_gripper' parent:='world' xyz:='0 0 0' rpy:='0 0 0' coupler:='true' gazebo:='false'">

    <!-- Used for connecting gripper to other link -->
    <xacro:if value="${parent == 'world'}">
      <link name="world"/>
    </xacro:if>

    <xacro:if value="${coupler}">
      <!-- <joint name="${gripper_name}_coupler_joint" type="fixed">
        <parent link="${parent}"/>
        <child link="${gripper_name}_base_coupler_link"/>
        <origin rpy="${rpy}" xyz="${xyz}"/>
      </joint> -->

      <!-- <link name="${gripper_name}_coupler_link">
        <inertial>
          <origin xyz="0.0 0.0 0.0" rpy="0 0 0" />
          <mass value="1.0" />
          <inertia ixx="0.0" ixy="0.0" ixz="0.0" iyy="0.0" iyz="0.0" izz="0.0" />
        </inertial>
        <visual>
          <origin xyz="0 0 0" rpy="0 0 0" />
          <geometry>
            <mesh filename="package://dual_description/meshes/visual/others/quick_change_tool.stl" scale="0.001 0.001 0.001" />
          </geometry>
          <material name="grey"/>
        </visual>
        <collision>
          <origin xyz="0 0 0" rpy="0 0 0" />
          <geometry>
            <mesh filename="package://dual_description/meshes/collision/others/quick_change_tool.stl" scale="0.001 0.001 0.001" />
          </geometry>
        </collision>
      </link> -->

      <joint name="${gripper_name}_base_coupler_joint" type="fixed">
        <origin xyz="0 0 0.01" rpy="0 0 1.57" />
        <parent link="${parent}"/>
        <child link="${gripper_name}_base_coupler_link"/>
      </joint>
      
      <link name="${gripper_name}_base_coupler_link">
        <visual>
          <geometry>
            <mesh filename="package://dual_description/meshes/visual/robotiq/robotiq_gripper_coupling.stl" scale="0.001 0.001 0.001" />
          </geometry>
          <material name="grey"/>
        </visual>
        <collision>
          <geometry>
            <mesh filename="package://dual_description/meshes/visual/robotiq/robotiq_gripper_coupling.stl" scale="0.001 0.001 0.001" />
          </geometry>
        </collision>
        <inertial>
          <origin xyz="2.073e-05   1.45286e-03  -1.1049e-03" rpy="0 0 0" />
          <mass value="0.168" />
          <inertia ixx="6.69695624e-05" ixy="5.21511788e-09" ixz="-2.74383009e-08" 
                   iyy="7.85088161e-05" iyz="5.41105193e-07" izz="1.41819717e-04"/>
        </inertial>
      </link>

      <joint name="${gripper_name}_fixed_joint" type="fixed">
        <parent link="${gripper_name}_base_coupler_link"/>
        <child link="${gripper_name}_base_link"/>
        <origin rpy="0.0 0.0 0.0" xyz="0 0 0.007"/>
      </joint>
    </xacro:if>

    <xacro:unless value="${coupler}">
      <joint name="${gripper_name}_fixed_joint" type="fixed">
        <parent link="${parent}"/>
        <child link="${gripper_name}_base_link"/>
        <origin rpy="0.0 0.0 0.0" xyz="0 0 0.007"/>
      </joint>
    </xacro:unless>

    <xacro:base_link prefix="${gripper_name}"/>
    <xacro:finger_links prefix="${gripper_name}" fingerprefix="left" stroke="85"/>
    <xacro:finger_links prefix="${gripper_name}" fingerprefix="right" stroke="85"/>
    <xacro:left_finger_joint prefix="${gripper_name}"/>
    <xacro:right_finger_joint prefix="${gripper_name}"/>
    <xacro:robotiq_arg2f_transmission prefix="${gripper_name}"/>

    <xacro:if value="${gazebo}">
      <xacro:right_finger_mimic_gazebo prefix="${gripper_name}"/>
      <xacro:inner_mimic_gazebo prefix="${gripper_name}" fingerprefix="left"/>
      <xacro:inner_mimic_gazebo prefix="${gripper_name}" fingerprefix="right"/>
    </xacro:if>

  </xacro:macro>
</robot>
